<?xml version="1.0" ?>
<sdf version='1.7'>
  <world name='world_demo'>
    <physics name="1ms" type="ode">
      <max_step_size>0.001</max_step_size> 
      <real_time_factor>1.0</real_time_factor>
    </physics>
    <plugin
      filename="gz-sim-physics-system"
      name="gz::sim::systems::Physics">
    </plugin>
    <plugin
      filename="gz-sim-user-commands-system"
      name="gz::sim::systems::UserCommands">
    </plugin>
    <plugin
      filename="gz-sim-scene-broadcaster-system"
      name="gz::sim::systems::SceneBroadcaster">
    </plugin>

    <gui fullscreen="0">

      <!-- 3D scene -->
      <plugin filename="MinimalScene" name="3D View">
        <gz-gui>
          <title>3D View</title>
          <property type="bool" key="showTitleBar">false</property>
          <property type="string" key="state">docked</property>
        </gz-gui>

        <engine>ogre2</engine>
        <scene>scene</scene>
        <ambient_light>0.5 0.5 0.5</ambient_light>
        <background_color>0.8 0.8 0.8</background_color>
        <camera_pose>-4.0 -4.0 2.5 0 0.4 0.8</camera_pose>
        <camera_clip>
          <near>0.01</near>
          <far>5000</far>
        </camera_clip>
      </plugin>
      <plugin filename="GzSceneManager" name="Scene Manager">
        <gz-gui>
          <property key="resizable" type="bool">false</property>
          <property key="width" type="double">5</property>
          <property key="height" type="double">5</property>
          <property key="state" type="string">floating</property>
          <property key="showTitleBar" type="bool">false</property>
        </gz-gui>
      </plugin>

      <!-- World control -->
      <plugin filename="WorldControl" name="World control">
        <gz-gui>
          <title>World control</title>
          <property type="bool" key="showTitleBar">false</property>
          <property type="bool" key="resizable">false</property>
          <property type="double" key="height">72</property>
          <property type="double" key="width">121</property>
          <property type="double" key="z">1</property>

          <property type="string" key="state">floating</property>
          <anchors target="3D View">
          <line own="left" target="left"/>
          <line own="bottom" target="bottom"/>
          </anchors>
        </gz-gui>

        <play_pause>true</play_pause>
        <step>true</step>
        <start_paused>false</start_paused>
        <service>/world/world_demo/control</service>
        <stats_topic>/world/world_demo/stats</stats_topic>
      </plugin>
      
      <!-- World statistics -->
      <plugin filename="WorldStats" name="World stats">
        <gz-gui>
          <title>World stats</title>
          <property type="bool" key="showTitleBar">false</property>
          <property type="bool" key="resizable">false</property>
          <property type="double" key="height">110</property>
          <property type="double" key="width">290</property>
          <property type="double" key="z">1</property>

          <property type="string" key="state">floating</property>
          <anchors target="3D View">
          <line own="right" target="right"/>
          <line own="bottom" target="bottom"/>
          </anchors>
        </gz-gui>
        <sim_time>true</sim_time>
        <real_time>true</real_time>
        <real_time_factor>true</real_time_factor>
        <iterations>true</iterations>
        <topic>/world/world_demo/stats</topic>

      </plugin>
      
      <!-- Toolbar (required for camera controls) -->
      <plugin filename="InteractiveViewControl" name="View Angle">
        <gz-gui>
          <title>View Angle</title>
          <property type="bool" key="showTitleBar">false</property>
          <property type="string" key="state">docked</property>
        </gz-gui>
      </plugin>

      <!-- Display Transform Control Toolbar -->
      <plugin filename="TransformControl" name="Transform Control">
        <gz-gui>
          <property type="bool" key="showTitleBar">false</property>
         <property type="string" key="state">docked</property>
        </gz-gui>
      </plugin>
        
      <!-- Entity tree -->
      <plugin filename="EntityTree" name="Entity tree">
      </plugin>

      <!--using keyboard to control arm-->
      <plugin filename="KeyPublisher" name="Key Publisher"/>
    </gui>

    <!--Light-->
    <light type="directional" name="sun">
      <cast_shadows>true</cast_shadows>
      <pose>0 0 10 0 0 0</pose>
      <diffuse>0.8 0.8 0.8 1</diffuse>
      <specular>0.2 0.2 0.2 1</specular>
      <attenuation>
        <range>1000</range>
        <constant>0.9</constant>
        <linear>0.01</linear>
        <quadratic>0.001</quadratic>
      </attenuation>
      <direction>-0.5 0.1 -0.9</direction>
    </light>  

    <!--Build a ground plane-->
    <model name='ground_plane'>
      <static>true</static>
      <pose>0 0 -0.01 0 0 0</pose> <link name='link'>
        <collision name='collision'>
          <geometry>
             <box>
              <size>20 20 0.02</size> </box>
          </geometry>
        </collision>
        <visual name='visual'>
          <geometry>
            <box>
              <size>20 20 0.02</size>
            </box>
          </geometry>
          <material>
            <ambient>0.5 0.5 0.5 1</ambient>
            <diffuse>0.5 0.5 0.5 1</diffuse>
          </material>
         </visual>
      </link>
    </model>

      <!--Robot itself-->
    <model name='UR3_Assembly_URDF'>

	    <joint name='fixed_base_joint' type='fixed'> <!--double check this joint-->
        <pose relative_to='__model__'>0 0 0 0 0 0</pose>
        <parent>world</parent>
        <child>base_link</child>
      </joint>  

      <link name='base_link'>
        <inertial>
          <pose>0 -4.4408920985006301e-16 0.047576249398130099 0 0 0</pose>
          <mass>2.6514504391646798</mass>
          <inertia>
            <ixx>0.00437179269564763</ixx>
            <ixy>-3.85185988877447e-34</ixy>
            <ixz>-5.8778619151101097e-23</ixz>
            <iyy>0.00437179269564763</iyy>
            <iyz>3.8514866752464201e-19</iyz>
            <izz>0.0043848087297314103</izz>
          </inertia>
        </inertial>
        <collision name='base_link_collision'>
          <pose>0 0 0 0 0 0</pose>
          <geometry>
            <mesh>
              <scale>1 1 1</scale>
              <uri>package:///home/user/car_spraying_ws/src/car_spraying_robot/meshes/base_link.stl</uri>
            </mesh>
          </geometry>
        </collision>
        <visual name='base_link_visual'>
          <pose>0 0 0 0 0 0</pose>
          <geometry>
            <mesh>
              <scale>1 1 1</scale>
              <uri>package:///home/user/car_spraying_ws/src/car_spraying_robot/meshes/base_link.stl</uri>
            </mesh>
          </geometry>
          <material>
            <diffuse>1 1 1 1</diffuse>
            <ambient>1 1 1 1</ambient>
          </material>
        </visual>
      </link>
      <joint name='joint_0' type='revolute'>
        <pose relative_to='base_link'>0 0 0.10580000000000001 0 0 0</pose>
        <parent>base_link</parent>
        <child>link_1</child>
        <axis>
          <xyz>0 0 1</xyz>
          <limit>
            <lower>-3.14</lower>
            <upper>3.14</upper>
            <effort>35</effort>
            <velocity>1.5</velocity>
          </limit>
          <dynamics>
            <spring_reference>0</spring_reference>
            <spring_stiffness>0</spring_stiffness>
          </dynamics>
        </axis>
      </joint>
      <plugin
     name="gz::sim::systems::JointPositionController"
     filename="gz-sim-joint-position-controller-system">
      <!-- gz-sim-joint-position-controller-system handles:
        Topic Subscriptions, PID, Motion Control  -->
        <joint_name>joint_0</joint_name>
        <topic>/joint_0/position_cmd</topic>
        <p_gain>2000</p_gain>
	      <i_gain>0.1</i_gain>
	      <d_gain>50</d_gain>
      </plugin>

      <link name='link_1'>
        <pose relative_to='joint_0'>0 0 0 0 0 0</pose>
        <inertial>
          <pose>0.0051135862154434398 -4.4893697648262804e-09 0.063179880887965001 0 0 0</pose>
          <mass>0.80599855297885203</mass>
          <inertia>
            <ixx>0.0013206547966630299</ixx>
            <ixy>4.4061962049193298e-10</ixy>
            <ixz>-1.7219218437347999e-05</ixz>
            <iyy>0.00142111571223347</iyy>
            <iyz>1.2940043194443099e-10</iyz>
            <izz>0.00096650730830554095</izz>
          </inertia>
        </inertial>
        <collision name='link_1_collision'>
          <pose>0 0 0 0 0 0</pose>
          <geometry>
            <mesh>
              <scale>1 1 1</scale>
              <uri>package:///home/user/car_spraying_ws/src/car_spraying_robot/meshes/link_1.stl</uri>
            </mesh>
          </geometry>
        </collision>
        <visual name='link_1_visual'>
          <pose>0 0 0 0 0 0</pose>
          <geometry>
            <mesh>
              <scale>1 1 1</scale>
              <uri>package:///home/user/car_spraying_ws/src/car_spraying_robot/meshes/link_1.stl</uri>
            </mesh>
          </geometry>
          <material>
            <diffuse>0.372549027 0.372549027 0.372549027 1</diffuse>
            <ambient>0.372549027 0.372549027 0.372549027 1</ambient>
          </material>
        </visual>
      </link>
      <joint name='joint_1' type='revolute'>
        <pose relative_to='link_1'>0.055000000000000597 0 0.065999999999999906 1.5707963267949003 5.5511151231257827e-17 -1.5707963267949003</pose>
        <parent>link_1</parent>
        <child>link_2</child>
        <axis>
          <xyz>0 0 1</xyz>
          <limit>
            <lower>-3.14</lower>
            <upper>3.14</upper>
            <effort>35</effort>
            <velocity>1.5</velocity>
          </limit>
          <dynamics>
            <spring_reference>0</spring_reference>
            <spring_stiffness>0</spring_stiffness>
          </dynamics>
        </axis>
      </joint>

      <plugin
    name="gz::sim::systems::JointPositionController"
    filename="gz-sim-joint-position-controller-system">
        <joint_name>joint_1</joint_name>
        <topic>/joint_1/position_cmd</topic>
        <p_gain>2000</p_gain>
	      <i_gain>0.1</i_gain>
	      <d_gain>50</d_gain>
      </plugin>

      <link name='link_2'>
        <pose relative_to='joint_1'>0 0 0 0 0 0</pose>
        <inertial>
          <pose>4.25462332032112e-10 0.112619000509759 -0.069311980854205799 0 0 0</pose>
          <mass>2.8455664040750701</mass>
          <inertia>
            <ixx>0.0058537691504215996</ixx>
            <ixy>6.5781848149650896e-10</ixy>
            <ixz>-6.7615934400463402e-11</ixz>
            <iyy>0.0029568682326097401</iyy>
            <iyz>2.1932095980722101e-05</iyz>
            <izz>0.0050912983881171402</izz>
          </inertia>
        </inertial>
        <collision name='link_2_collision'>
          <pose>0 0 0 0 0 0</pose>
          <geometry>
            <mesh>
              <scale>1 1 1</scale>
              <uri>package:///home/user/car_spraying_ws/src/car_spraying_robot/meshes/link_2.stl</uri>
            </mesh>
          </geometry>
        </collision>
        <visual name='link_2_visual'>
          <pose>0 0 0 0 0 0</pose>
          <geometry>
            <mesh>
              <scale>1 1 1</scale>
              <uri>package:///home/user/car_spraying_ws/src/car_spraying_robot/meshes/link_2.stl</uri>
            </mesh>
          </geometry>
          <material>
            <diffuse>0.372549027 0.372549027 0.372549027 1</diffuse>
            <ambient>0.372549027 0.372549027 0.372549027 1</ambient>
          </material>
        </visual>
      </link>
      <joint name='joint_2' type='revolute'>
        <pose relative_to='link_2'>0 0.255 -0.015999999999999601 0 0 1.5707963267949003</pose>
        <parent>link_2</parent>
        <child>link_3</child>
        <axis>
          <xyz>0 0 1</xyz>
          <limit>
            <lower>-3.14</lower>
            <upper>3.14</upper>
            <effort>10</effort>
            <velocity>2</velocity>
          </limit>
          <dynamics>
            <spring_reference>0</spring_reference>
            <spring_stiffness>0</spring_stiffness>
          </dynamics>
        </axis>
      </joint>

      <plugin
    name="gz::sim::systems::JointPositionController"
    filename="gz-sim-joint-position-controller-system">
        <joint_name>joint_2</joint_name>
        <topic>/joint_2/position_cmd</topic>
        <p_gain>2000</p_gain>
	      <i_gain>0.1</i_gain>
	      <d_gain>50</d_gain>
      </plugin>

      <link name='link_3'>
        <pose relative_to='joint_2'>0 0 0 0 0 0</pose>
        <inertial>
          <pose>0.115582187515874 3.7597396307376097e-09 0.047877780898351902 0 0 0</pose>
          <mass>1.5490639003480999</mass>
          <inertia>
            <ixx>0.00090639954169275804</ixx>
            <ixy>5.9464801384745095e-10</ixy>
            <ixz>-5.8943171541064503e-05</ixz>
            <iyy>0.0023187378831417702</iyy>
            <iyz>1.8360356982654398e-11</iyz>
            <izz>0.002197605373301</izz>
          </inertia>
        </inertial>
        <collision name='link_3_collision'>
          <pose>0 0 0 0 0 0</pose>
          <geometry>
            <mesh>
              <scale>1 1 1</scale>
              <uri>package:///home/user/car_spraying_ws/src/car_spraying_robot/meshes/link_3.stl</uri>
            </mesh>
          </geometry>
        </collision>
        <visual name='link_3_visual'>
          <pose>0 0 0 0 0 0</pose>
          <geometry>
            <mesh>
              <scale>1 1 1</scale>
              <uri>package:///home/user/car_spraying_ws/src/car_spraying_robot/meshes/link_3.stl</uri>
            </mesh>
          </geometry>
          <material>
            <diffuse>0.372549027 0.372549027 0.372549027 1</diffuse>
            <ambient>0.372549027 0.372549027 0.372549027 1</ambient>
          </material>
        </visual>
      </link>
      <joint name='joint_3' type='revolute'>
        <pose relative_to='link_3'>0.22450000000000001 0 0.0070000000000001198 -3.14159265358979 0 0</pose>
        <parent>link_3</parent>
        <child>link_4</child>
        <axis>
          <xyz>0 0 1</xyz>
          <limit>
            <lower>-3.14</lower>
            <upper>3.14</upper>
            <effort>10</effort>
            <velocity>2</velocity>
          </limit>
          <dynamics>
            <spring_reference>0</spring_reference>
            <spring_stiffness>0</spring_stiffness>
          </dynamics>
        </axis>
      </joint>

      <plugin
    name="gz::sim::systems::JointPositionController"
    filename="gz-sim-joint-position-controller-system">
        <joint_name>joint_3</joint_name>
        <topic>/joint_3/position_cmd</topic>
        <p_gain>2000</p_gain>
	      <i_gain>0.1</i_gain>
	      <d_gain>50</d_gain>
      </plugin>
      
      <link name='link_4'>
        <pose relative_to='joint_3'>0 0 0 0 0 0</pose>
        <inertial>
          <pose>-0.00250614919525627 1.9986776678138102e-09 0.036195883903732601 0 0 0</pose>
          <mass>0.30592412248425099</mass>
          <inertia>
            <ixx>0.00019256180376239399</ixx>
            <ixy>2.03197911773492e-11</ixy>
            <ixz>1.2865620793401399e-06</ixz>
            <iyy>0.00028193000710771601</iyy>
            <iyz>6.7479130275890594e-11</iyz>
            <izz>0.000261214129591347</izz>
          </inertia>
        </inertial>
        <collision name='link_4_collision'>
          <pose>0 0 0 0 0 0</pose>
          <geometry>
            <mesh>
              <scale>1 1 1</scale>
              <uri>package:///home/user/car_spraying_ws/src/car_spraying_robot/meshes/link_4.stl</uri>
            </mesh>
          </geometry>
        </collision>
        <visual name='link_4_visual'>
          <pose>0 0 0 0 0 0</pose>
          <geometry>
            <mesh>
              <scale>1 1 1</scale>
              <uri>package:///home/user/car_spraying_ws/src/car_spraying_robot/meshes/link_4.stl</uri>
            </mesh>
          </geometry>
          <material>
            <diffuse>0.127450988 0.127450988 0.127450988 1</diffuse>
            <ambient>0.127450988 0.127450988 0.127450988 1</ambient>
          </material>
        </visual>
      </link>
      <joint name='joint_4' type='revolute'>
        <pose relative_to='link_4'>0.042999999999999997 0 0.040500000000000203 1.5707963267949003 -5.5511151231257827e-17 1.5707963267949003</pose>
        <parent>link_4</parent>
        <child>link_5</child>
        <axis>
          <xyz>0 0 1</xyz>
          <limit>
            <lower>-3.14</lower>
            <upper>3.14</upper>
            <effort>10</effort>
            <velocity>2</velocity>
          </limit>
          <dynamics>
            <spring_reference>0</spring_reference>
            <spring_stiffness>0</spring_stiffness>
          </dynamics>
        </axis>
      </joint>

      <plugin
    name="gz::sim::systems::JointPositionController"
    filename="gz-sim-joint-position-controller-system">
        <joint_name>joint_4</joint_name>
        <topic>/joint_4/position_cmd</topic>
        <p_gain>2000</p_gain>
	      <i_gain>0.1</i_gain>
	      <d_gain>50</d_gain>
      </plugin>

      <link name='link_5'>
        <pose relative_to='joint_4'>0 0 0 0 0 0</pose>
        <inertial>
          <pose>-3.0539069051371801e-09 0.00190124611504094 0.0365748109896381 0 0 0</pose>
          <mass>0.33545705692010602</mass>
          <inertia>
            <ixx>0.000353929483232228</ixx>
            <ixy>-2.6343744776887e-11</ixy>
            <ixz>-9.1711257278252205e-11</ixz>
            <iyy>0.000208608865865198</iyy>
            <iyz>-4.0576736704203102e-06</iyz>
            <izz>0.00033276362468715202</izz>
          </inertia>
        </inertial>
        <collision name='link_5_collision'>
          <pose>0 0 0 0 0 0</pose>
          <geometry>
            <mesh>
              <scale>1 1 1</scale>
              <uri>package:///home/user/car_spraying_ws/src/car_spraying_robot/meshes/link_5.stl</uri>
            </mesh>
          </geometry>
        </collision>
        <visual name='link_5_visual'>
          <pose>0 0 0 0 0 0</pose>
          <geometry>
            <mesh>
              <scale>1 1 1</scale>
              <uri>package:///home/user/car_spraying_ws/src/car_spraying_robot/meshes/link_5.stl</uri>
            </mesh>
          </geometry>
          <material>
            <diffuse>0.127450988 0.127450988 0.127450988 1</diffuse>
            <ambient>0.127450988 0.127450988 0.127450988 1</ambient>
          </material>
        </visual>
      </link>
      <joint name='joint_5' type='revolute'>
        <pose relative_to='link_5'>0 0.053000000000000803 0.0404999999999998 -1.5707963267949003 0 0</pose>
        <parent>link_5</parent>
        <child>link_6</child>
        <axis>
          <xyz>0 0 -1</xyz>
          <limit>
            <lower>-3.14</lower>
            <upper>3.14</upper>
            <effort>10</effort>
            <velocity>2</velocity>
          </limit>
          <dynamics>
            <spring_reference>0</spring_reference>
            <spring_stiffness>0</spring_stiffness>
          </dynamics>
        </axis>
      </joint>

      <plugin
    name="gz::sim::systems::JointPositionController"
    filename="gz-sim-joint-position-controller-system">
        <joint_name>joint_5</joint_name>
        <topic>/joint_5/position_cmd</topic>
        <p_gain>2000</p_gain>
	      <i_gain>0.1</i_gain>
	      <d_gain>50</d_gain>
      </plugin>

      <link name='link_6'>
        <pose relative_to='joint_5'>0 0 0 0 0 0</pose>
        <inertial>
          <pose>-3.1086244689504399e-15 0.00071908520638130902 0.019083861771335801 0 0 0</pose>
          <mass>0.32019667334485702</mass>
          <inertia>
            <ixx>0.00011646073524573</ixx>
            <ixy>3.2444412836329997e-20</ixy>
            <ixz>-5.9770531959501001e-20</ixz>
            <iyy>0.000114323636606439</iyy>
            <iyz>2.1268307275844302e-06</iyz>
            <izz>0.00016425413209485899</izz>
          </inertia>
        </inertial>
        <collision name='link_6_collision'>
          <pose>0 0 0 0 0 0</pose>
          <geometry>
            <mesh>
              <scale>1 1 1</scale>
              <uri>package:///home/user/car_spraying_ws/src/car_spraying_robot/meshes/link_6.stl</uri>
            </mesh>
          </geometry>
        </collision>
        <visual name='link_6_visual'>
          <pose>0 0 0 0 0 0</pose>
          <geometry>
            <mesh>
              <scale>1 1 1</scale>
              <uri>package:///home/user/car_spraying_ws/src/car_spraying_robot/meshes/link_6.stl</uri>
            </mesh>
          </geometry>
          <material>
            <diffuse>0.127450988 0.127450988 0.127450988 1</diffuse>
            <ambient>0.127450988 0.127450988 0.127450988 1</ambient>
          </material>
        </visual>
      </link>
      <plugin 
        filename="gz-sim-joint-state-publisher-system"
        name="gz::sim::systems::JointStatePublisher">
          <joint_name>joint_0</joint_name>
          <joint_name>joint_1</joint_name>
          <joint_name>joint_2</joint_name>
          <joint_name>joint_3</joint_name>
          <joint_name>joint_4</joint_name>
          <joint_name>joint_5</joint_name>
          <update_rate>100</update_rate>
          <topic>/world/world_demo/joint_state</topic>
      </plugin>
      <!-- <plugin 
        filename="gz_ros2_control-system" 
        name="gz_ros2_control::GazeboSimROS2ControlPlugin">
        <parameters>/home/user/car_spraying_ws/src/car_spraying_moveit_config/config/ros2_controllers.yaml</parameters>
      </plugin> -->
    </model>
  </world>
</sdf>
